Workbook

Sheet Prospectos Resumen
A1: PRESOL — Prospectos | Resumen Ejecutivo
A2: Dirección · Filtrar por Categoría, Corredor o Ciudad · Completar libremente “Nota Dirección”
A4: TOTAL | C4: CLASE A | E4: CLASE B | G4: CLASE C | I4: TELÉFONOS OK | K4: A VERIFICAR
A5: =COUNTA(Prospectos!A2:A288) -> 287 | C5: =COUNTIF(Prospectos!F2:F288,"A") -> 162 | E5: =COUNTIF(Prospectos!F2:F288,"B") -> 110 | G5: =COUNTIF(Prospectos!F2:F288,"C") -> 15 | I5: =COUNTIF(Prospectos!L2:L288,"OK") -> 198 | K5: =COUNTIF(Prospectos!L2:L288,"<>OK") -> 89
A8: ID | B8: Clase | C8: Empresa | D8: Categoría comercial | E8: Corredor | F8: Ciudad | G8: Teléfonos | H8: Preguntar por | I8: Necesidad probable | J8: Prioridad de visita | K8: Nota Dirección
A9: RT-054 | B9: =IFERROR(INDEX(Prospectos!$F$2:$F$288,MATCH($A9,Prospectos!$A$2:$A$288,0)),"") -> A | C9: =IFERROR(INDEX(Prospectos!$H$2:$H$288,MATCH($A9,Prospectos!$A$2:$A$288,0)),"") -> Ascanelli S.A. | D9: =IFERROR(INDEX(Prospectos!$J$2:$J$288,MATCH($A9,Prospectos!$A$2:$A$288,0)),"") -> Maquinaria agrícola | E9: =IFERROR(INDEX(Prospectos!$C$2:$C$288,MATCH($A9,Prospectos!$A$2:$A$288,0)),"") -> Base Río Tercero | F9: =IFERROR(INDEX(Prospectos!$E$2:$E$288,MATCH($A9,Prospectos!$A$2:$A$288,0)),"") -> Río Tercero | G9: =IFERROR(INDEX(Prospectos!$K$2:$K$288,MATCH($A9,Prospectos!$A$2:$A$288,0)),"") -> 03571 423691 | H9: =IFERROR(INDEX(Prospectos!$M$2:$M$288,MATCH($A9,Prospectos!$A$2:$A$288,0)),"") -> logística / ventas / postventa | I9: =IFERROR(INDEX(Prospectos!$N$2:$N$288,MATCH($A9,Prospectos!$A$2:$A$288,0)),"") -> Despacho de implementos, tolvas, sembradoras, estructuras, equipos terminados y componentes de gran porte hacia concesionarios, clientes, ferias o campo. | J9: =IFERROR(INDEX(Prospectos!$AJ$2:$AJ$288,MATCH($A9,Prospectos!$A$2:$A$288,0)),"") -> Muy alta | K9: SERGIO ASCANELLI
A10: RT-001 | B10: =IFERROR(INDEX(Prospectos!$F$2:$F$288,MATCH($A10,Prospectos!$A$2:$A$288,0)),"") -> A | C10: =IFERROR(INDEX(Prospectos!$H$2:$H$288,MATCH($A10,Prospectos!$A$2:$A$288,0)),"") -> Hormicor | D10: =IFERROR(INDEX(Prospectos!$J$2:$J$288,MATCH($A10,Prospectos!$A$2:$A$288,0)),"") -> Hormigón, áridos y materiales | E10: =IFERROR(INDEX(Prospectos!$C$2:$C$288,MATCH($A10,Prospectos!$A$2:$A$288,0)),"") -> Base Río Tercero | F10: =IFERROR(INDEX(Prospectos!$E$2:$E$288,MATCH($A10,Prospectos!$A$2:$A$288,0)),"") -> Río Tercero | G10: =IFERROR(INDEX(Prospectos!$K$2:$K$288,MATCH($A10,Prospectos!$A$2:$A$288,0)),"") -> 03571 500888 / 03571 510066 | H10: =IFERROR(INDEX(Prospectos!$M$2:$M$288,MATCH($A10,Prospectos!$A$2:$A$288,0)),"") -> planta / mantenimiento | I10: =IFERROR(INDEX(Prospectos!$N$2:$N$288,MATCH($A10,Prospectos!$A$2:$A$288,0)),"") -> Movimiento de premoldeados, equipos de planta/cantera, bombas, moldes y cargas pesadas. | J10: =IFERROR(INDEX(Prospectos!$AJ$2:$AJ$288,MATCH($A10,Prospectos!$A$2:$A$288,0)),"") -> Muy alta
A11: RT-002 | B11: =IFERROR(INDEX(Prospectos!$F$2:$F$288,MATCH($A11,Prospectos!$A$2:$A$288,0)),"") -> A | C11: =IFERROR(INDEX(Prospectos!$H$2:$H$288,MATCH($A11,Prospectos!$A$2:$A$288,0)),"") -> Metalúrgica Monticelli | D11: =IFERROR(INDEX(Prospectos!$J$2:$J$288,MATCH($A11,Prospectos!$A$2:$A$288,0)),"") -> Maquinaria agrícola | E11: =IFERROR(INDEX(Prospectos!$C$2:$C$288,MATCH($A11,Prospectos!$A$2:$A$288,0)),"") -> Base Río Tercero | F11: =IFERROR(INDEX(Prospectos!$E$2:$E$288,MATCH($A11,Prospectos!$A$2:$A$288,0)),"") -> Río Tercero | G11: =IFERROR(INDEX(Prospectos!$K$2:$K$288,MATCH($A11,Prospectos!$A$2:$A$288,0)),"") -> +54 3571 613058 / +54 3571 613060 | H11: =IFERROR(INDEX(Prospectos!$M$2:$M$288,MATCH($A11,Prospectos!$A$2:$A$288,0)),"") -> logística / despacho / postventa | I11: =IFERROR(INDEX(Prospectos!$N$2:$N$288,MATCH($A11,Prospectos!$A$2:$A$288,0)),"") -> Traslado de maquinaria, implementos, equipos terminados y componentes de gran porte entre planta, cliente, obra o feria. | J11: =IFERROR(INDEX(Prospectos!$AJ$2:$AJ$288,MATCH($A11,Prospectos!$A$2:$A$288,0)),"") -> Muy alta | K11: GUILLERMO GOÑI
A12: RT-003 | B12: =IFERROR(INDEX(Prospectos!$F$2:$F$288,MATCH($A12,Prospectos!$A$2:$A$288,0)),"") -> A | C12: =IFERROR(INDEX(Prospectos!$H$2:$H$288,MATCH($A12,Prospectos!$A$2:$A$288,0)),"") -> Metalúrgica Novaretti | D12: =IFERROR(INDEX(Prospectos!$J$2:$J$288,MATCH($A12,Prospectos!$A$2:$A$288,0)),"") -> Metalúrgica y fabricación | E12: =IFERROR(INDEX(Prospectos!$C$2:$C$288,MATCH($A12,Prospectos!$A$2:$A$288,0)),"") -> Base Río Tercero | F12: =IFERROR(INDEX(Prospectos!$E$2:$E$288,MATCH($A12,Prospectos!$A$2:$A$288,0)),"") -> Río Tercero | G12: =IFERROR(INDEX(Prospectos!$K$2:$K$288,MATCH($A12,Prospectos!$A$2:$A$288,0)),"") -> 03571 414282 / 03571 606930 | H12: =IFERROR(INDEX(Prospectos!$M$2:$M$288,MATCH($A12,Prospectos!$A$2:$A$288,0)),"") -> despacho / producción | I12: =IFERROR(INDEX(Prospectos!$N$2:$N$288,MATCH($A12,Prospectos!$A$2:$A$288,0)),"") -> Despacho seguro de estructuras, carrozados, tanques, piezas industriales y equipos sobre plataforma. | J12: =IFERROR(INDEX(Prospectos!$AJ$2:$AJ$288,MATCH($A12,Prospectos!$A$2:$A$288,0)),"") -> Muy alta | K12: CRISTIAN NOVARETTI
A13: RT-004 | B13: =IFERROR(INDEX(Prospectos!$F$2:$F$288,MATCH($A13,Prospectos!$A$2:$A$288,0)),"") -> A | C13: =IFERROR(INDEX(Prospectos!$H$2:$H$288,MATCH($A13,Prospectos!$A$2:$A$288,0)),"") -> Metalúrgica Río Tercero S.A. | D13: =IFERROR(INDEX(Prospectos!$J$2:$J$288,MATCH($A13,Prospectos!$A$2:$A$288,0)),"") -> Metalúrgica y fabricación | E13: =IFERROR(INDEX(Prospectos!$C$2:$C$288,MATCH($A13,Prospectos!$A$2:$A$288,0)),"") -> Base Río Tercero | F13: =IFERROR(INDEX(Prospectos!$E$2:$E$288,MATCH($A13,Prospectos!$A$2:$A$288,0)),"") -> Río Tercero | G13: =IFERROR(INDEX(Prospectos!$K$2:$K$288,MATCH($A13,Prospectos!$A$2:$A$288,0)),"") -> 03571 430558 | H13: =IFERROR(INDEX(Prospectos!$M$2:$M$288,MATCH($A13,Prospectos!$A$2:$A$288,0)),"") -> despacho / producción | I13: =IFERROR(INDEX(Prospectos!$N$2:$N$288,MATCH($A13,Prospectos!$A$2:$A$288,0)),"") -> Traslado de equipos de planta, silos, repuestos pesados, balanzas, implementos y cargas especiales. | J13: =IFERROR(INDEX(Prospectos!$AJ$2:$AJ$288,MATCH($A13,Prospectos!$A$2:$A$288,0)),"") -> Muy alta | K13: FEDE SERRA
A14: RT-005 | B14: =IFERROR(INDEX(Prospectos!$F$2:$F$288,MATCH($A14,Prospectos!$A$2:$A$288,0)),"") -> A | C14: =IFERROR(INDEX(Prospectos!$H$2:$H$288,MATCH($A14,Prospectos!$A$2:$A$288,0)),"") -> NT Construcciones | D14: =IFERROR(INDEX(Prospectos!$J$2:$J$288,MATCH($A14,Prospectos!$A$2:$A$288,0)),"") -> Construcción y obra vial | E14: =IFERROR(INDEX(Prospectos!$C$2:$C$288,MATCH($A14,Prospectos!$A$2:$A$288,0)),"") -> Base Río Tercero | F14: =IFERROR(INDEX(Prospectos!$E$2:$E$288,MATCH($A14,Prospectos!$A$2:$A$288,0)),"") -> Río Tercero | G14: =IFERROR(INDEX(Prospectos!$K$2:$K$288,MATCH($A14,Prospectos!$A$2:$A$288,0)),"") -> +54 9 3571 597645 | H14: =IFERROR(INDEX(Prospectos!$M$2:$M$288,MATCH($A14,Prospectos!$A$2:$A$288,0)),"") -> operaciones / jefe de obra | I14: =IFERROR(INDEX(Prospectos!$N$2:$N$288,MATCH($A14,Prospectos!$A$2:$A$288,0)),"") -> Traslado de maquinaria, módulos de obrador, estructuras, equipos y cargas pesadas entre frentes. | J14: =IFERROR(INDEX(Prospectos!$AJ$2:$AJ$288,MATCH($A14,Prospectos!$A$2:$A$288,0)),"") -> Muy alta
A15: RT-064 | B15: =IFERROR(INDEX(Prospectos!$F$2:$F$288,MATCH($A15,Prospectos!$A$2:$A$288,0)),"") -> A | C15: =IFERROR(INDEX(Prospectos!$H$2:$H$288,MATCH($A15,Prospectos!$A$2:$A$288,0)),"") -> SALA / Agrotecnología Sala — Río Tercero | D15: =IFERROR(INDEX(Prospectos!$J$2:$J$288,MATCH($A15,Prospectos!$A$2:$A$288,0)),"") -> Maquinaria agrícola | E15: =IFERROR(INDEX(Prospectos!$C$2:$C$288,MATCH($A15,Prospectos!$A$2:$A$288,0)),"") -> Base Río Tercero | F15: =IFERROR(INDEX(Prospectos!$E$2:$E$288,MATCH($A15,Prospectos!$A$2:$A$288,0)),"") -> Río Tercero | G15: =IFERROR(INDEX(Prospectos!$K$2:$K$288,MATCH($A15,Prospectos!$A$2:$A$288,0)),"") -> +54 9 358 4843387 | H15: =IFERROR(INDEX(Prospectos!$M$2:$M$288,MATCH($A15,Prospectos!$A$2:$A$288,0)),"") -> logística / entregas / usados / postventa / gerente comercial | I15: =IFERROR(INDEX(Prospectos!$N$2:$N$288,MATCH($A15,Prospectos!$A$2:$A$288,0)),"") -> Entrega y retiro de tractores, cosechadoras, pulverizadoras, sembradoras e implementos; movimientos por ventas, canjes, usados, service, demostraciones y ferias. | J15: =IFERROR(INDEX(Prospectos!$AJ$2:$AJ$288,MATCH($A15,Prospectos!$A$2:$A$288,0)),"") -> Muy alta
A16: RT-006 | B16: =IFERROR(INDEX(Prospectos!$F$2:$F$288,MATCH($A16,Prospectos!$A$2:$A$288,0)),"") -> A | C16: =IFERROR(INDEX(Prospectos!$H$2:$H$288,MATCH($A16,Prospectos!$A$2:$A$288,0)),"") -> Sinfix SAS | D16: =IFERROR(INDEX(Prospectos!$J$2:$J$288,MATCH($A16,Prospectos!$A$2:$A$288,0)),"") -> Metalúrgica y fabricación | E16: =IFERROR(INDEX(Prospectos!$C$2:$C$288,MATCH($A16,Prospectos!$A$2:$A$288,0)),"") -> Base Río Tercero | F16: =IFERROR(INDEX(Prospectos!$E$2:$E$288,MATCH($A16,Prospectos!$A$2:$A$288,0)),"") -> Río Tercero | G16: =IFERROR(INDEX(Prospectos!$K$2:$K$288,MATCH($A16,Prospectos!$A$2:$A$288,0)),"") -> +54 9 3571 405077 | H16: =IFERROR(INDEX(Prospectos!$M$2:$M$288,MATCH($A16,Prospectos!$A$2:$A$288,0)),"") -> despacho / producción | I16: =IFERROR(INDEX(Prospectos!$N$2:$N$288,MATCH($A16,Prospectos!$A$2:$A$288,0)),"") -> Despacho de estructuras, piezas, equipos y conjuntos metalmecánicos de gran porte hacia obras o clientes. | J16: =IFERROR(INDEX(Prospectos!$AJ$2:$AJ$288,MATCH($A16,Prospectos!$A$2:$A$288,0)),"") -> Muy alta
A17: RT-007 | B17: =IFERROR(INDEX(Prospectos!$F$2:$F$288,MATCH($A17,Prospectos!$A$2:$A$288,0)),"") -> A | C17: =IFERROR(INDEX(Prospectos!$H$2:$H$288,MATCH($A17,Prospectos!$A$2:$A$288,0)),"") -> Suragro - Implementos Agrícolas | D17: =IFERROR(INDEX(Prospectos!$J$2:$J$288,MATCH($A17,Prospectos!$A$2:$A$288,0)),"") -> Maquinaria agrícola | E17: =IFERROR(INDEX(Prospectos!$C$2:$C$288,MATCH($A17,Prospectos!$A$2:$A$288,0)),"") -> Base Río Tercero | F17: =IFERROR(INDEX(Prospectos!$E$2:$E$288,MATCH($A17,Prospectos!$A$2:$A$288,0)),"") -> Río Tercero | G17: =IFERROR(INDEX(Prospectos!$K$2:$K$288,MATCH($A17,Prospectos!$A$2:$A$288,0)),"") -> 03571 424574 | H17: =IFERROR(INDEX(Prospectos!$M$2:$M$288,MATCH($A17,Prospectos!$A$2:$A$288,0)),"") -> logística / despacho / postventa | I17: =IFERROR(INDEX(Prospectos!$N$2:$N$288,MATCH($A17,Prospectos!$A$2:$A$288,0)),"") -> Traslado de maquinaria, implementos, equipos terminados y componentes de gran porte entre planta, cliente, obra o feria. | J17: =IFERROR(INDEX(Prospectos!$AJ$2:$AJ$288,MATCH($A17,Prospectos!$A$2:$A$288,0)),"") -> Muy alta
A18: RT-008 | B18: =IFERROR(INDEX(Prospectos!$F$2:$F$288,MATCH($A18,Prospectos!$A$2:$A$288,0)),"") -> A | C18: =IFERROR(INDEX(Prospectos!$H$2:$H$288,MATCH($A18,Prospectos!$A$2:$A$288,0)),"") -> Tres Eme S.A. | D18: =IFERROR(INDEX(Prospectos!$J$2:$J$288,MATCH($A18,Prospectos!$A$2:$A$288,0)),"") -> Agro, acopio y cooperativas | E18: =IFERROR(INDEX(Prospectos!$C$2:$C$288,MATCH($A18,Prospectos!$A$2:$A$288,0)),"") -> Base Río Tercero | F18: =IFERROR(INDEX(Prospectos!$E$2:$E$288,MATCH($A18,Prospectos!$A$2:$A$288,0)),"") -> Río Tercero | G18: =IFERROR(INDEX(Prospectos!$K$2:$K$288,MATCH($A18,Prospectos!$A$2:$A$288,0)),"") -> 03571 432190 / 03571 637720 | H18: =IFERROR(INDEX(Prospectos!$M$2:$M$288,MATCH($A18,Prospectos!$A$2:$A$288,0)),"") -> responsable de acopio / mantenimiento | I18: =IFERROR(INDEX(Prospectos!$N$2:$N$288,MATCH($A18,Prospectos!$A$2:$A$288,0)),"") -> Traslado de equipos de planta, silos, repuestos pesados, balanzas, implementos y cargas especiales. | J18: =IFERROR(INDEX(Prospectos!$AJ$2:$AJ$288,MATCH($A18,Prospectos!$A$2:$A$288,0)),"") -> Muy alta | K18: MATI MENGO
A19: RT-009 | B19: =IFERROR(INDEX(Prospectos!$F$2:$F$288,MATCH($A19,Prospectos!$A$2:$A$288,0)),"") -> A | C19: =IFERROR(INDEX(Prospectos!$H$2:$H$288,MATCH($A19,Prospectos!$A$2:$A$288,0)),"") -> Vial del Centro | D19: =IFERROR(INDEX(Prospectos!$J$2:$J$288,MATCH($A19,Prospectos!$A$2:$A$288,0)),"") -> Construcción y obra vial | E19: =IFERROR(INDEX(Prospectos!$C$2:$C$288,MATCH($A19,Prospectos!$A$2:$A$288,0)),"") -> Base Río Tercero | F19: =IFERROR(INDEX(Prospectos!$E$2:$E$288,MATCH($A19,Prospectos!$A$2:$A$288,0)),"") -> Río Tercero | G19: =IFERROR(INDEX(Prospectos!$K$2:$K$288,MATCH($A19,Prospectos!$A$2:$A$288,0)),"") -> 0351 6411413 | H19: =IFERROR(INDEX(Prospectos!$M$2:$M$288,MATCH($A19,Prospectos!$A$2:$A$288,0)),"") -> operaciones / entregas | I19: =IFERROR(INDEX(Prospectos!$N$2:$N$288,MATCH($A19,Prospectos!$A$2:$A$288,0)),"") -> Traslado de maquinaria, módulos de obrador, estructuras, equipos y cargas pesadas entre frentes. | J19: =IFERROR(INDEX(Prospectos!$AJ$2:$AJ$288,MATCH($A19,Prospectos!$A$2:$A$288,0)),"") -> Muy alta
A20: RT-010 | B20: =IFERROR(INDEX(Prospectos!$F$2:$F$288,MATCH($A20,Prospectos!$A$2:$A$288,0)),"") -> A | C20: =IFERROR(INDEX(Prospectos!$H$2:$H$288,MATCH($A20,Prospectos!$A$2:$A$288,0)),"") -> HORMIWORK S.A. | D20: =IFERROR(INDEX(Prospectos!$J$2:$J$288,MATCH($A20,Prospectos!$A$2:$A$288,0)),"") -> Hormigón, áridos y materiales | E20: =IFERROR(INDEX(Prospectos!$C$2:$C$288,MATCH($A20,Prospectos!$A$2:$A$288,0)),"") -> Base Río Tercero | F20: =IFERROR(INDEX(Prospectos!$E$2:$E$288,MATCH($A20,Prospectos!$A$2:$A$288,0)),"") -> Río Tercero | G20: =IFERROR(INDEX(Prospectos!$K$2:$K$288,MATCH($A20,Prospectos!$A$2:$A$288,0)),"") -> 03571 565662 (portería parque) | H20: =IFERROR(INDEX(Prospectos!$M$2:$M$288,MATCH($A20,Prospectos!$A$2:$A$288,0)),"") -> planta / despacho | I20: =IFERROR(INDEX(Prospectos!$N$2:$N$288,MATCH($A20,Prospectos!$A$2:$A$288,0)),"") -> Movimiento de premoldeados, moldes, equipos de planta y cargas pesadas asociadas a obra. | J20: =IFERROR(INDEX(Prospectos!$AJ$2:$AJ$288,MATCH($A20,Prospectos!$A$2:$A$288,0)),"") -> Alta
A21: RT-062 | B21: =IFERROR(INDEX(Prospectos!$F$2:$F$288,MATCH($A21,Prospectos!$A$2:$A$288,0)),"") -> A | C21: =IFERROR(INDEX(Prospectos!$H$2:$H$288,MATCH($A21,Prospectos!$A$2:$A$288,0)),"") -> Bartolomé Cerutti SRL — Río Tercero | D21: =IFERROR(INDEX(Prospectos!$J$2:$J$288,MATCH($A21,Prospectos!$A$2:$A$288,0)),"") -> Maquinaria agrícola | E21: =IFERROR(INDEX(Prospectos!$C$2:$C$288,MATCH($A21,Prospectos!$A$2:$A$288,0)),"") -> Base Río Tercero | F21: =IFERROR(INDEX(Prospectos!$E$2:$E$288,MATCH($A21,Prospectos!$A$2:$A$288,0)),"") -> Río Tercero | G21: =IFERROR(INDEX(Prospectos!$K$2:$K$288,MATCH($A21,Prospectos!$A$2:$A$288,0)),"") -> 03571 644022 | H21: =IFERROR(INDEX(Prospectos!$M$2:$M$288,MATCH($A21,Prospectos!$A$2:$A$288,0)),"") -> logística / ventas / postventa | I21: =IFERROR(INDEX(Prospectos!$N$2:$N$288,MATCH($A21,Prospectos!$A$2:$A$288,0)),"") -> Entrega y retiro de tractores, cosechadoras, pulverizadoras, sembradoras e implementos; movimientos por venta, service, canje, demostraciones o ferias. | J21: =IFERROR(INDEX(Prospectos!$AJ$2:$AJ$288,MATCH($A21,Prospectos!$A$2:$A$288,0)),"") -> Muy alta
A22: RT-055 | B22: =IFERROR(INDEX(Prospectos!$F$2:$F$288,MATCH($A22,Prospectos!$A$2:$A$288,0)),"") -> A | C22: =IFERROR(INDEX(Prospectos!$H$2:$H$288,MATCH($A22,Prospectos!$A$2:$A$288,0)),"") -> Conax | D22: =IFERROR(INDEX(Prospectos!$J$2:$J$288,MATCH($A22,Prospectos!$A$2:$A$288,0)),"") -> Maquinaria agrícola | E22: =IFERROR(INDEX(Prospectos!$C$2:$C$288,MATCH($A22,Prospectos!$A$2:$A$288,0)),"") -> Base Río Tercero | F22: =IFERROR(INDEX(Prospectos!$E$2:$E$288,MATCH($A22,Prospectos!$A$2:$A$288,0)),"") -> Río Tercero | G22: =IFERROR(INDEX(Prospectos!$K$2:$K$288,MATCH($A22,Prospectos!$A$2:$A$288,0)),"") -> +54 3571 348077 | H22: =IFERROR(INDEX(Prospectos!$M$2:$M$288,MATCH($A22,Prospectos!$A$2:$A$288,0)),"") -> logística / ventas / postventa | I22: =IFERROR(INDEX(Prospectos!$N$2:$N$288,MATCH($A22,Prospectos!$A$2:$A$288,0)),"") -> Entrega y retiro de tractores, cosechadoras, pulverizadoras, sembradoras e implementos; movimientos por venta, service, canje, demostraciones o ferias. | J22: =IFERROR(INDEX(Prospectos!$AJ$2:$AJ$288,MATCH($A22,Prospectos!$A$2:$A$288,0)),"") -> Muy alta | K22: GASPAR LOPEZ
A23: RT-056 | B23: =IFERROR(INDEX(Prospectos!$F$2:$F$288,MATCH($A23,Prospectos!$A$2:$A$288,0)),"") -> A | C23: =IFERROR(INDEX(Prospectos!$H$2:$H$288,MATCH($A23,Prospectos!$A$2:$A$288,0)),"") -> RSA Repuestos y Servicios | D23: =IFERROR(INDEX(Prospectos!$J$2:$J$288,MATCH($A23,Prospectos!$A$2:$A$288,0)),"") -> Maquinaria agrícola | E23: =IFERROR(INDEX(Prospectos!$C$2:$C$288,MATCH($A23,Prospectos!$A$2:$A$288,0)),"") -> Base Río Tercero | F23: =IFERROR(INDEX(Prospectos!$E$2:$E$288,MATCH($A23,Prospectos!$A$2:$A$288,0)),"") -> Río Tercero | G23: =IFERROR(INDEX(Prospectos!$K$2:$K$288,MATCH($A23,Prospectos!$A$2:$A$288,0)),"") -> +54 9 3571 538080 / +54 9 3571 578870 | H23: =IFERROR(INDEX(Prospectos!$M$2:$M$288,MATCH($A23,Prospectos!$A$2:$A$288,0)),"") -> logística / ventas / postventa | I23: =IFERROR(INDEX(Prospectos!$N$2:$N$288,MATCH($A23,Prospectos!$A$2:$A$288,0)),"") -> Entrega y retiro de tractores, cosechadoras, pulverizadoras, sembradoras e implementos; movimientos por venta, service, canje, demostraciones o ferias. | J23: =IFERROR(INDEX(Prospectos!$AJ$2:$AJ$288,MATCH($A23,Prospectos!$A$2:$A$288,0)),"") -> Muy alta
A24: RT-057 | B24: =IFERROR(INDEX(Prospectos!$F$2:$F$288,MATCH($A24,Prospectos!$A$2:$A$288,0)),"") -> A | C24: =IFERROR(INDEX(Prospectos!$H$2:$H$288,MATCH($A24,Prospectos!$A$2:$A$288,0)),"") -> Viejo Tala S.R.L. — Río Tercero | D24: =IFERROR(INDEX(Prospectos!$J$2:$J$288,MATCH($A24,Prospectos!$A$2:$A$288,0)),"") -> Maquinaria agrícola | E24: =IFERROR(INDEX(Prospectos!$C$2:$C$288,MATCH($A24,Prospectos!$A$2:$A$288,0)),"") -> Base Río Tercero | F24: =IFERROR(INDEX(Prospectos!$E$2:$E$288,MATCH($A24,Prospectos!$A$2:$A$288,0)),"") -> Río Tercero | G24: =IFERROR(INDEX(Prospectos!$K$2:$K$288,MATCH($A24,Prospectos!$A$2:$A$288,0)),"") -> 03571 643332 / +54 9 353 4221837 | H24: =IFERROR(INDEX(Prospectos!$M$2:$M$288,MATCH($A24,Prospectos!$A$2:$A$288,0)),"") -> logística / ventas / postventa | I24: =IFERROR(INDEX(Prospectos!$N$2:$N$288,MATCH($A24,Prospectos!$A$2:$A$288,0)),"") -> Entrega y retiro de tractores, cosechadoras, pulverizadoras, sembradoras e implementos; movimientos por venta, service, canje, demostraciones o ferias. | J24: =IFERROR(INDEX(Prospectos!$AJ$2:$AJ$288,MATCH($A24,Prospectos!$A$2:$A$288,0)),"") -> Muy alta | K24: VISTOR SEIA (HERNANDO) WALTER PAYOLA (RIO 3)
A25: RT-065 | B25: =IFERROR(INDEX(Prospectos!$F$2:$F$288,MATCH($A25,Prospectos!$A$2:$A$288,0)),"") -> A | C25: =IFERROR(INDEX(Prospectos!$H$2:$H$288,MATCH($A25,Prospectos!$A$2:$A$288,0)),"") -> Rino Maquinaria | D25: =IFERROR(INDEX(Prospectos!$J$2:$J$288,MATCH($A25,Prospectos!$A$2:$A$288,0)),"") -> Maquinaria agrícola | E25: =IFERROR(INDEX(Prospectos!$C$2:$C$288,MATCH($A25,Prospectos!$A$2:$A$288,0)),"") -> Base Río Tercero | F25: =IFERROR(INDEX(Prospectos!$E$2:$E$288,MATCH($A25,Prospectos!$A$2:$A$288,0)),"") -> Río Tercero | G25: =IFERROR(INDEX(Prospectos!$K$2:$K$288,MATCH($A25,Prospectos!$A$2:$A$288,0)),"") -> +54 9 3571 681323 | H25: =IFERROR(INDEX(Prospectos!$M$2:$M$288,MATCH($A25,Prospectos!$A$2:$A$288,0)),"") -> logística / entregas / usados / postventa / gerente comercial | I25: =IFERROR(INDEX(Prospectos!$N$2:$N$288,MATCH($A25,Prospectos!$A$2:$A$288,0)),"") -> Entrega y retiro de tractores, cosechadoras, pulverizadoras, sembradoras e implementos; movimientos por ventas, canjes, usados, service, demostraciones y ferias. | J25: =IFERROR(INDEX(Prospectos!$AJ$2:$AJ$288,MATCH($A25,Prospectos!$A$2:$A$288,0)),"") -> Alta
A26: RT-011 | B26: =IFERROR(INDEX(Prospectos!$F$2:$F$288,MATCH($A26,Prospectos!$A$2:$A$288,0)),"") -> A | C26: =IFERROR(INDEX(Prospectos!$H$2:$H$288,MATCH($A26,Prospectos!$A$2:$A$288,0)),"") -> Alpha Construcciones Industriales S.A. | D26: =IFERROR(INDEX(Prospectos!$J$2:$J$288,MATCH($A26,Prospectos!$A$2:$A$288,0)),"") -> Construcción y obra vial | E26: =IFERROR(INDEX(Prospectos!$C$2:$C$288,MATCH($A26,Prospectos!$A$2:$A$288,0)),"") -> Base Río Tercero | F26: =IFERROR(INDEX(Prospectos!$E$2:$E$288,MATCH($A26,Prospectos!$A$2:$A$288,0)),"") -> Río Tercero | G26: =IFERROR(INDEX(Prospectos!$K$2:$K$288,MATCH($A26,Prospectos!$A$2:$A$288,0)),"") -> A relevar | H26: =IFERROR(INDEX(Prospectos!$M$2:$M$288,MATCH($A26,Prospectos!$A$2:$A$288,0)),"") -> jefe de obra / operaciones | I26: =IFERROR(INDEX(Prospectos!$N$2:$N$288,MATCH($A26,Prospectos!$A$2:$A$288,0)),"") -> Traslado de maquinaria, módulos de obrador, estructuras y equipos entre depósitos y frentes de obra. | J26: =IFERROR(INDEX(Prospectos!$AJ$2:$AJ$288,MATCH($A26,Prospectos!$A$2:$A$288,0)),"") -> Alta
A27: RT-012 | B27: =IFERROR(INDEX(Prospectos!$F$2:$F$288,MATCH($A27,Prospectos!$A$2:$A$288,0)),"") -> A | C27: =IFERROR(INDEX(Prospectos!$H$2:$H$288,MATCH($A27,Prospectos!$A$2:$A$288,0)),"") -> Caon - Concesionario Oficial CASE IH | D27: =IFERROR(INDEX(Prospectos!$J$2:$J$288,MATCH($A27,Prospectos!$A$2:$A$288,0)),"") -> Maquinaria agrícola | E27: =IFERROR(INDEX(Prospectos!$C$2:$C$288,MATCH($A27,Prospectos!$A$2:$A$288,0)),"") -> Base Río Tercero | F27: =IFERROR(INDEX(Prospectos!$E$2:$E$288,MATCH($A27,Prospectos!$A$2:$A$288,0)),"") -> Río Tercero | G27: =IFERROR(INDEX(Prospectos!$K$2:$K$288,MATCH($A27,Prospectos!$A$2:$A$288,0)),"") -> 03571 682141 | H27: =IFERROR(INDEX(Prospectos!$M$2:$M$288,MATCH($A27,Prospectos!$A$2:$A$288,0)),"") -> logística / entregas / postventa | I27: =IFERROR(INDEX(Prospectos!$N$2:$N$288,MATCH($A27,Prospectos!$A$2:$A$288,0)),"") -> Traslado de maquinaria agrícola o vial entre sucursal, cliente, taller, campo y eventos. | J27: =IFERROR(INDEX(Prospectos!$AJ$2:$AJ$288,MATCH($A27,Prospectos!$A$2:$A$288,0)),"") -> Muy alta
A28: RT-013 | B28: =IFERROR(INDEX(Prospectos!$F$2:$F$288,MATCH($A28,Prospectos!$A$2:$A$288,0)),"") -> A | C28: =IFERROR(INDEX(Prospectos!$H$2:$H$288,MATCH($A28,Prospectos!$A$2:$A$288,0)),"") -> Cimat SRL | D28: =IFERROR(INDEX(Prospectos!$J$2:$J$288,MATCH($A28,Prospectos!$A$2:$A$288,0)),"") -> Maquinaria agrícola | E28: =IFERROR(INDEX(Prospectos!$C$2:$C$288,MATCH($A28,Prospectos!$A$2:$A$288,0)),"") -> Base Río Tercero | F28: =IFERROR(INDEX(Prospectos!$E$2:$E$288,MATCH($A28,Prospectos!$A$2:$A$288,0)),"") -> Río Tercero | G28: =IFERROR(INDEX(Prospectos!$K$2:$K$288,MATCH($A28,Prospectos!$A$2:$A$288,0)),"") -> 03571 422153 | H28: =IFERROR(INDEX(Prospectos!$M$2:$M$288,MATCH($A28,Prospectos!$A$2:$A$288,0)),"") -> logística / entregas / postventa | I28: =IFERROR(INDEX(Prospectos!$N$2:$N$288,MATCH($A28,Prospectos!$A$2:$A$288,0)),"") -> Traslado de maquinaria agrícola o vial entre sucursal, cliente, taller, campo y eventos. | J28: =IFERROR(INDEX(Prospectos!$AJ$2:$AJ$288,MATCH($A28,Prospectos!$A$2:$A$288,0)),"") -> Muy alta | K28: RAUL ARUTA
A29: RT-014 | B29: =IFERROR(INDEX(Prospectos!$F$2:$F$288,MATCH($A29,Prospectos!$A$2:$A$288,0)),"") -> A | C29: =IFERROR(INDEX(Prospectos!$H$2:$H$288,MATCH($A29,Prospectos!$A$2:$A$288,0)),"") -> D & M ESTRUCTURAS | D29: =IFERROR(INDEX(Prospectos!$J$2:$J$288,MATCH($A29,Prospectos!$A$2:$A$288,0)),"") -> Metalúrgica y fabricación | E29: =IFERROR(INDEX(Prospectos!$C$2:$C$288,MATCH($A29,Prospectos!$A$2:$A$288,0)),"") -> Base Río Tercero | F29: =IFERROR(INDEX(Prospectos!$E$2:$E$288,MATCH($A29,Prospectos!$A$2:$A$288,0)),"") -> Río Tercero | G29: =IFERROR(INDEX(Prospectos!$K$2:$K$288,MATCH($A29,Prospectos!$A$2:$A$288,0)),"") -> A relevar | H29: =IFERROR(INDEX(Prospectos!$M$2:$M$288,MATCH($A29,Prospectos!$A$2:$A$288,0)),"") -> despacho / producción | I29: =IFERROR(INDEX(Prospectos!$N$2:$N$288,MATCH($A29,Prospectos!$A$2:$A$288,0)),"") -> Despacho de estructuras, piezas, equipos y conjuntos metalmecánicos de gran porte hacia obras o clientes. | J29: =IFERROR(INDEX(Prospectos!$AJ$2:$AJ$288,MATCH($A29,Prospectos!$A$2:$A$288,0)),"") -> Alta | K29: PABLO PONCETI
A30: RT-015 | B30: =IFERROR(INDEX(Prospectos!$F$2:$F$288,MATCH($A30,Prospectos!$A$2:$A$288,0)),"") -> A | C30: =IFERROR(INDEX(Prospectos!$H$2:$H$288,MATCH($A30,Prospectos!$A$2:$A$288,0)),"") -> Duter S.A. | D30: =IFERROR(INDEX(Prospectos!$J$2:$J$288,MATCH($A30,Prospectos!$A$2:$A$288,0)),"") -> Maquinaria agrícola | E30: =IFERROR(INDEX(Prospectos!$C$2:$C$288,MATCH($A30,Prospectos!$A$2:$A$288,0)),"") -> Base Río Tercero | F30: =IFERROR(INDEX(Prospectos!$E$2:$E$288,MATCH($A30,Prospectos!$A$2:$A$288,0)),"") -> Río Tercero | G30: =IFERROR(INDEX(Prospectos!$K$2:$K$288,MATCH($A30,Prospectos!$A$2:$A$288,0)),"") -> 03571 565177 | H30: =IFERROR(INDEX(Prospectos!$M$2:$M$288,MATCH($A30,Prospectos!$A$2:$A$288,0)),"") -> logística / despacho / postventa | I30: =IFERROR(INDEX(Prospectos!$N$2:$N$288,MATCH($A30,Prospectos!$A$2:$A$288,0)),"") -> Traslado de maquinaria, implementos, equipos terminados y componentes de gran porte entre planta, cliente, obra o feria. | J30: =IFERROR(INDEX(Prospectos!$AJ$2:$AJ$288,MATCH($A30,Prospectos!$A$2:$A$288,0)),"") -> Muy alta
A31: RT-016 | B31: =IFERROR(INDEX(Prospectos!$F$2:$F$288,MATCH($A31,Prospectos!$A$2:$A$288,0)),"") -> A | C31: =IFERROR(INDEX(Prospectos!$H$2:$H$288,MATCH($A31,Prospectos!$A$2:$A$288,0)),"") -> ESISA | D31: =IFERROR(INDEX(Prospectos!$J$2:$J$288,MATCH($A31,Prospectos!$A$2:$A$288,0)),"") -> Módulos y contenedores | E31: =IFERROR(INDEX(Prospectos!$C$2:$C$288,MATCH($A31,Prospectos!$A$2:$A$288,0)),"") -> Base Río Tercero | F31: =IFERROR(INDEX(Prospectos!$E$2:$E$288,MATCH($A31,Prospectos!$A$2:$A$288,0)),"") -> Río Tercero | G31: =IFERROR(INDEX(Prospectos!$K$2:$K$288,MATCH($A31,Prospectos!$A$2:$A$288,0)),"") -> Portería parque: 03571 565662; mail esisaservicios@gmail.com | H31: =IFERROR(INDEX(Prospectos!$M$2:$M$288,MATCH($A31,Prospectos!$A$2:$A$288,0)),"") -> operaciones / entregas | I31: =IFERROR(INDEX(Prospectos!$N$2:$N$288,MATCH($A31,Prospectos!$A$2:$A$288,0)),"") -> Entrega, descarga y posicionamiento de módulos/containers en obra o cliente final. | J31: =IFERROR(INDEX(Prospectos!$AJ$2:$AJ$288,MATCH($A31,Prospectos!$A$2:$A$288,0)),"") -> Muy alta
A32: RT-017 | B32: =IFERROR(INDEX(Prospectos!$F$2:$F$288,MATCH($A32,Prospectos!$A$2:$A$288,0)),"") -> A | C32: =IFERROR(INDEX(Prospectos!$H$2:$H$288,MATCH($A32,Prospectos!$A$2:$A$288,0)),"") -> ISECO Construcción | D32: =IFERROR(INDEX(Prospectos!$J$2:$J$288,MATCH($A32,Prospectos!$A$2:$A$288,0)),"") -> Construcción y obra vial | E32: =IFERROR(INDEX(Prospectos!$C$2:$C$288,MATCH($A32,Prospectos!$A$2:$A$288,0)),"") -> Base Río Tercero | F32: =IFERROR(INDEX(Prospectos!$E$2:$E$288,MATCH($A32,Prospectos!$A$2:$A$288,0)),"") -> Río Tercero | G32: =IFERROR(INDEX(Prospectos!$K$2:$K$288,MATCH($A32,Prospectos!$A$2:$A$288,0)),"") -> +54 9 3571 551917 | H32: =IFERROR(INDEX(Prospectos!$M$2:$M$288,MATCH($A32,Prospectos!$A$2:$A$288,0)),"") -> jefe de obra / operaciones | I32: =IFERROR(INDEX(Prospectos!$N$2:$N$288,MATCH($A32,Prospectos!$A$2:$A$288,0)),"") -> Traslado de maquinaria, módulos de obrador, estructuras y equipos entre depósitos y frentes de obra. | J32: =IFERROR(INDEX(Prospectos!$AJ$2:$AJ$288,MATCH($A32,Prospectos!$A$2:$A$288,0)),"") -> Muy alta | K32: BETO
A33: RT-018 | B33: =IFERROR(INDEX(Prospectos!$F$2:$F$288,MATCH($A33,Prospectos!$A$2:$A$288,0)),"") -> A | C33: =IFERROR(INDEX(Prospectos!$H$2:$H$288,MATCH($A33,Prospectos!$A$2:$A$288,0)),"") -> Luzenti Hnos S.A. | D33: =IFERROR(INDEX(Prospectos!$J$2:$J$288,MATCH($A33,Prospectos!$A$2:$A$288,0)),"") -> Construcción y obra vial | E33: =IFERROR(INDEX(Prospectos!$C$2:$C$288,MATCH($A33,Prospectos!$A$2:$A$288,0)),"") -> Base Río Tercero | F33: =IFERROR(INDEX(Prospectos!$E$2:$E$288,MATCH($A33,Prospectos!$A$2:$A$288,0)),"") -> Río Tercero | G33: =IFERROR(INDEX(Prospectos!$K$2:$K$288,MATCH($A33,Prospectos!$A$2:$A$288,0)),"") -> 03584 860532 | H33: =IFERROR(INDEX(Prospectos!$M$2:$M$288,MATCH($A33,Prospectos!$A$2:$A$288,0)),"") -> jefe de obra / operaciones | I33: =IFERROR(INDEX(Prospectos!$N$2:$N$288,MATCH($A33,Prospectos!$A$2:$A$288,0)),"") -> Traslado de maquinaria, módulos de obrador, estructuras y equipos entre depósitos y frentes de obra. | J33: =IFERROR(INDEX(Prospectos!$AJ$2:$AJ$288,MATCH($A33,Prospectos!$A$2:$A$288,0)),"") -> Muy alta | K33: JORGE LUCENTI
A34: RT-019 | B34: =IFERROR(INDEX(Prospectos!$F$2:$F$288,MATCH($A34,Prospectos!$A$2:$A$288,0)),"") -> A | C34: =IFERROR(INDEX(Prospectos!$H$2:$H$288,MATCH($A34,Prospectos!$A$2:$A$288,0)),"") -> NEMETAL S.A.S | D34: =IFERROR(INDEX(Prospectos!$J$2:$J$288,MATCH($A34,Prospectos!$A$2:$A$288,0)),"") -> Maquinaria agrícola | E34: =IFERROR(INDEX(Prospectos!$C$2:$C$288,MATCH($A34,Prospectos!$A$2:$A$288,0)),"") -> Base Río Tercero | F34: =IFERROR(INDEX(Prospectos!$E$2:$E$288,MATCH($A34,Prospectos!$A$2:$A$288,0)),"") -> Río Tercero | G34: =IFERROR(INDEX(Prospectos!$K$2:$K$288,MATCH($A34,Prospectos!$A$2:$A$288,0)),"") -> 03571 550608 | H34: =IFERROR(INDEX(Prospectos!$M$2:$M$288,MATCH($A34,Prospectos!$A$2:$A$288,0)),"") -> despacho / producción | I34: =IFERROR(INDEX(Prospectos!$N$2:$N$288,MATCH($A34,Prospectos!$A$2:$A$288,0)),"") -> Despacho de estructuras, piezas, equipos y conjuntos metalmecánicos de gran porte hacia obras o clientes. | J34: =IFERROR(INDEX(Prospectos!$AJ$2:$AJ$288,MATCH($A34,Prospectos!$A$2:$A$288,0)),"") -> Muy alta
A35: RT-058 | B35: =IFERROR(INDEX(Prospectos!$F$2:$F$288,MATCH($A35,Prospectos!$A$2:$A$288,0)),"") -> A | C35: =IFERROR(INDEX(Prospectos!$H$2:$H$288,MATCH($A35,Prospectos!$A$2:$A$288,0)),"") -> Paulucci Máquinas Agrícolas | D35: =IFERROR(INDEX(Prospectos!$J$2:$J$288,MATCH($A35,Prospectos!$A$2:$A$288,0)),"") -> Maquinaria agrícola | E35: =IFERROR(INDEX(Prospectos!$C$2:$C$288,MATCH($A35,Prospectos!$A$2:$A$288,0)),"") -> Base Río Tercero | F35: =IFERROR(INDEX(Prospectos!$E$2:$E$288,MATCH($A35,Prospectos!$A$2:$A$288,0)),"") -> Río Tercero | G35: =IFERROR(INDEX(Prospectos!$K$2:$K$288,MATCH($A35,Prospectos!$A$2:$A$288,0)),"") -> 03571 424384 | H35: =IFERROR(INDEX(Prospectos!$M$2:$M$288,MATCH($A35,Prospectos!$A$2:$A$288,0)),"") -> logística / ventas / postventa | I35: =IFERROR(INDEX(Prospectos!$N$2:$N$288,MATCH($A35,Prospectos!$A$2:$A$288,0)),"") -> Entrega y retiro de tractores, cosechadoras, pulverizadoras, sembradoras e implementos; movimientos por venta, service, canje, demostraciones o ferias. | J35: =IFERROR(INDEX(Prospectos!$AJ$2:$AJ$288,MATCH($A35,Prospectos!$A$2:$A$288,0)),"") -> Alta | K35: WALTER PAULUCCI
A36: RT-059 | B36: =IFERROR(INDEX(Prospectos!$F$2:$F$288,MATCH($A36,Prospectos!$A$2:$A$288,0)),"") -> A | C36: =IFERROR(INDEX(Prospectos!$H$2:$H$288,MATCH($A36,Prospectos!$A$2:$A$288,0)),"") -> SAEMMA | D36: =IFERROR(INDEX(Prospectos!$J$2:$J$288,MATCH($A36,Prospectos!$A$2:$A$288,0)),"") -> Maquinaria agrícola | E36: =IFERROR(INDEX(Prospectos!$C$2:$C$288,MATCH($A36,Prospectos!$A$2:$A$288,0)),"") -> Base Río Tercero | F36: =IFERROR(INDEX(Prospectos!$E$2:$E$288,MATCH($A36,Prospectos!$A$2:$A$288,0)),"") -> Río Tercero | G36: =IFERROR(INDEX(Prospectos!$K$2:$K$288,MATCH($A36,Prospectos!$A$2:$A$288,0)),"") -> 03571 432338 | H36: =IFERROR(INDEX(Prospectos!$M$2:$M$288,MATCH($A36,Prospectos!$A$2:$A$288,0)),"") -> logística / ventas / postventa | I36: =IFERROR(INDEX(Prospectos!$N$2:$N$288,MATCH($A36,Prospectos!$A$2:$A$288,0)),"") -> Entrega y retiro de tractores, cosechadoras, pulverizadoras, sembradoras e implementos; movimientos por venta, service, canje, demostraciones o ferias. | J36: =IFERROR(INDEX(Prospectos!$AJ$2:$AJ$288,MATCH($A36,Prospectos!$A$2:$A$288,0)),"") -> Alta
A37: RT-020 | B37: =IFERROR(INDEX(Prospectos!$F$2:$F$288,MATCH($A37,Prospectos!$A$2:$A$288,0)),"") -> A | C37: =IFERROR(INDEX(Prospectos!$H$2:$H$288,MATCH($A37,Prospectos!$A$2:$A$288,0)),"") -> Sclauzero Metalúrgica | D37: =IFERROR(INDEX(Prospectos!$J$2:$J$288,MATCH($A37,Prospectos!$A$2:$A$288,0)),"") -> Metalúrgica y fabricación | E37: =IFERROR(INDEX(Prospectos!$C$2:$C$288,MATCH($A37,Prospectos!$A$2:$A$288,0)),"") -> Base Río Tercero | F37: =IFERROR(INDEX(Prospectos!$E$2:$E$288,MATCH($A37,Prospectos!$A$2:$A$288,0)),"") -> Río Tercero | G37: =IFERROR(INDEX(Prospectos!$K$2:$K$288,MATCH($A37,Prospectos!$A$2:$A$288,0)),"") -> 03571 414014 | H37: =IFERROR(INDEX(Prospectos!$M$2:$M$288,MATCH($A37,Prospectos!$A$2:$A$288,0)),"") -> despacho / producción | I37: =IFERROR(INDEX(Prospectos!$N$2:$N$288,MATCH($A37,Prospectos!$A$2:$A$288,0)),"") -> Despacho de estructuras, piezas, equipos y conjuntos metalmecánicos de gran porte hacia obras o clientes. | J37: =IFERROR(INDEX(Prospectos!$AJ$2:$AJ$288,MATCH($A37,Prospectos!$A$2:$A$288,0)),"") -> Muy alta | K37: GUILLERMO SCLAUSERO
A38: RT-060 | B38: =IFERROR(INDEX(Prospectos!$F$2:$F$288,MATCH($A38,Prospectos!$A$2:$A$288,0)),"") -> A | C38: =IFERROR(INDEX(Prospectos!$H$2:$H$288,MATCH($A38,Prospectos!$A$2:$A$288,0)),"") -> Barrax Argentina S.A. | D38: =IFERROR(INDEX(Prospectos!$J$2:$J$288,MATCH($A38,Prospectos!$A$2:$A$288,0)),"") -> Maquinaria agrícola | E38: =IFERROR(INDEX(Prospectos!$C$2:$C$288,MATCH($A38,Prospectos!$A$2:$A$288,0)),"") -> Base Río Tercero | F38: =IFERROR(INDEX(Prospectos!$E$2:$E$288,MATCH($A38,Prospectos!$A$2:$A$288,0)),"") -> Río Tercero | G38: =IFERROR(INDEX(Prospectos!$K$2:$K$288,MATCH($A38,Prospectos!$A$2:$A$288,0)),"") -> 03571 421774 / 03571 420576 | H38: =IFERROR(INDEX(Prospectos!$M$2:$M$288,MATCH($A38,Prospectos!$A$2:$A$288,0)),"") -> logística / ventas / postventa | I38: =IFERROR(INDEX(Prospectos!$N$2:$N$288,MATCH($A38,Prospectos!$A$2:$A$288,0)),"") -> Movimiento de agropartes, repuestos pesados, conjuntos y eventualmente implementos/equipos entre planta, concesionarios y clientes. | J38: =IFERROR(INDEX(Prospectos!$AJ$2:$AJ$288,MATCH($A38,Prospectos!$A$2:$A$288,0)),"") -> Alta
A39: RT-021 | B39: =IFERROR(INDEX(Prospectos!$F$2:$F$288,MATCH($A39,Prospectos!$A$2:$A$288,0)),"") -> A | C39: =IFERROR(INDEX(Prospectos!$H$2:$H$288,MATCH($A39,Prospectos!$A$2:$A$288,0)),"") -> IMBAL S.A. | D39: =IFERROR(INDEX(Prospectos!$J$2:$J$288,MATCH($A39,Prospectos!$A$2:$A$288,0)),"") -> Metalúrgica y fabricación | E39: =IFERROR(INDEX(Prospectos!$C$2:$C$288,MATCH($A39,Prospectos!$A$2:$A$288,0)),"") -> Base Río Tercero | F39: =IFERROR(INDEX(Prospectos!$E$2:$E$288,MATCH($A39,Prospectos!$A$2:$A$288,0)),"") -> Río Tercero | G39: =IFERROR(INDEX(Prospectos!$K$2:$K$288,MATCH($A39,Prospectos!$A$2:$A$288,0)),"") -> A relevar en terreno | H39: =IFERROR(INDEX(Prospectos!$M$2:$M$288,MATCH($A39,Prospectos!$A$2:$A$288,0)),"") -> despacho / producción | I39: =IFERROR(INDEX(Prospectos!$N$2:$N$288,MATCH($A39,Prospectos!$A$2:$A$288,0)),"") -> Despacho seguro de estructuras, carrozados, tanques, piezas industriales y equipos sobre plataforma. | J39: =IFERROR(INDEX(Prospectos!$AJ$2:$AJ$288,MATCH($A39,Prospectos!$A$2:$A$288,0)),"") -> Alta | K39: DANIEL BALATORE
A40: RT-022 | B40: =IFERROR(INDEX(Prospectos!$F$2:$F$288,MATCH($A40,Prospectos!$A$2:$A$288,0)),"") -> B | C40: =IFERROR(INDEX(Prospectos!$H$2:$H$288,MATCH($A40,Prospectos!$A$2:$A$288,0)),"") -> J.A.F. Plásticos Reforzados | D40: =IFERROR(INDEX(Prospectos!$J$2:$J$288,MATCH($A40,Prospectos!$A$2:$A$288,0)),"") -> PRFV y plásticos | E40: =IFERROR(INDEX(Prospectos!$C$2:$C$288,MATCH($A40,Prospectos!$A$2:$A$288,0)),"") -> Base Río Tercero | F40: =IFERROR(INDEX(Prospectos!$E$2:$E$288,MATCH($A40,Prospectos!$A$2:$A$288,0)),"") -> Río Tercero | G40: =IFERROR(INDEX(Prospectos!$K$2:$K$288,MATCH($A40,Prospectos!$A$2:$A$288,0)),"") -> 3571 533624 / 3571 579801 / portería parque 03571 565662 | H40: =IFERROR(INDEX(Prospectos!$M$2:$M$288,MATCH($A40,Prospectos!$A$2:$A$288,0)),"") -> producción / logística | I40: =IFERROR(INDEX(Prospectos!$N$2:$N$288,MATCH($A40,Prospectos!$A$2:$A$288,0)),"") -> Retiro, traslado y descarga de piletas/fibra o piezas voluminosas livianas, con cuidado de maniobra. | J40: =IFERROR(INDEX(Prospectos!$AJ$2:$AJ$288,MATCH($A40,Prospectos!$A$2:$A$288,0)),"") -> Alta
A41: RT-023 | B41: =IFERROR(INDEX(Prospectos!$F$2:$F$288,MATCH($A41,Prospectos!$A$2:$A$288,0)),"") -> B | C41: =IFERROR(INDEX(Prospectos!$H$2:$H$288,MATCH($A41,Prospectos!$A$2:$A$288,0)),"") -> Tecnipiscinas | D41: =IFERROR(INDEX(Prospectos!$J$2:$J$288,MATCH($A41,Prospectos!$A$2:$A$288,0)),"") -> PRFV y plásticos | E41: =IFERROR(INDEX(Prospectos!$C$2:$C$288,MATCH($A41,Prospectos!$A$2:$A$288,0)),"") -> Base Río Tercero | F41: =IFERROR(INDEX(Prospectos!$E$2:$E$288,MATCH($A41,Prospectos!$A$2:$A$288,0)),"") -> Río Tercero | G41: =IFERROR(INDEX(Prospectos!$K$2:$K$288,MATCH($A41,Prospectos!$A$2:$A$288,0)),"") -> +54 3571 412563 | H41: =IFERROR(INDEX(Prospectos!$M$2:$M$288,MATCH($A41,Prospectos!$A$2:$A$288,0)),"") -> ventas / logística / dueño | I41: =IFERROR(INDEX(Prospectos!$N$2:$N$288,MATCH($A41,Prospectos!$A$2:$A$288,0)),"") -> Retiro, traslado y descarga de piletas/fibra o piezas voluminosas livianas, con cuidado de maniobra. | J41: =IFERROR(INDEX(Prospectos!$AJ$2:$AJ$288,MATCH($A41,Prospectos!$A$2:$A$288,0)),"") -> Alta
A42: RT-024 | B42: =IFERROR(INDEX(Prospectos!$F$2:$F$288,MATCH($A42,Prospectos!$A$2:$A$288,0)),"") -> B | C42: =IFERROR(INDEX(Prospectos!$H$2:$H$288,MATCH($A42,Prospectos!$A$2:$A$288,0)),"") -> Indusplast Río Tercero | D42: =IFERROR(INDEX(Prospectos!$J$2:$J$288,MATCH($A42,Prospectos!$A$2:$A$288,0)),"") -> PRFV y plásticos | E42: =IFERROR(INDEX(Prospectos!$C$2:$C$288,MATCH($A42,Prospectos!$A$2:$A$288,0)),"") -> Base Río Tercero | F42: =IFERROR(INDEX(Prospectos!$E$2:$E$288,MATCH($A42,Prospectos!$A$2:$A$288,0)),"") -> Río Tercero | G42: =IFERROR(INDEX(Prospectos!$K$2:$K$288,MATCH($A42,Prospectos!$A$2:$A$288,0)),"") -> +54 3571 57-5556 | H42: =IFERROR(INDEX(Prospectos!$M$2:$M$288,MATCH($A42,Prospectos!$A$2:$A$288,0)),"") -> ventas / dueño | I42: =IFERROR(INDEX(Prospectos!$N$2:$N$288,MATCH($A42,Prospectos!$A$2:$A$288,0)),"") -> Retiro, traslado y descarga de piletas/fibra o piezas voluminosas livianas, con cuidado de maniobra. | J42: =IFERROR(INDEX(Prospectos!$AJ$2:$AJ$288,MATCH($A42,Prospectos!$A$2:$A$288,0)),"") -> Alta
A43: RT-025 | B43: =IFERROR(INDEX(Prospectos!$F$2:$F$288,MATCH($A43,Prospectos!$A$2:$A$288,0)),"") -> B | C43: =IFERROR(INDEX(Prospectos!$H$2:$H$288,MATCH($A43,Prospectos!$A$2:$A$288,0)),"") -> AGROTRAZIONE S.A.S | D43: =IFERROR(INDEX(Prospectos!$J$2:$J$288,MATCH($A43,Prospectos!$A$2:$A$288,0)),"") -> Maquinaria agrícola | E43: =IFERROR(INDEX(Prospectos!$C$2:$C$288,MATCH($A43,Prospectos!$A$2:$A$288,0)),"") -> Base Río Tercero | F43: =IFERROR(INDEX(Prospectos!$E$2:$E$288,MATCH($A43,Prospectos!$A$2:$A$288,0)),"") -> Río Tercero | G43: =IFERROR(INDEX(Prospectos!$K$2:$K$288,MATCH($A43,Prospectos!$A$2:$A$288,0)),"") -> 03571 528350 | H43: =IFERROR(INDEX(Prospectos!$M$2:$M$288,MATCH($A43,Prospectos!$A$2:$A$288,0)),"") -> logística / entregas / postventa | I43: =IFERROR(INDEX(Prospectos!$N$2:$N$288,MATCH($A43,Prospectos!$A$2:$A$288,0)),"") -> Traslado de maquinaria agrícola o vial entre sucursal, cliente, taller, campo y eventos. | J43: =IFERROR(INDEX(Prospectos!$AJ$2:$AJ$288,MATCH($A43,Prospectos!$A$2:$A$288,0)),"") -> Alta
...

Sheet Prospectos
A1: ID | B1: Estado de contacto | C1: Corredor | D1: Microzona | E1: Ciudad | F1: Clase | G1: Puntaje operativo | H1: Empresa | I1: Sector | J1: Categoría comercial | K1: Teléfonos | L1: Calidad del teléfono | M1: Preguntar por | N1: Necesidad probable | O1: Oferta PRESOL | P1: Gancho comercial | Q1: Acción sugerida | R1: Responsable | S1: Nota Dirección | T1: Resultado | U1: Fecha de visita | V1: Próximo paso | W1: Notas de campo | X1: Teléfono principal (tel:) | Y1: Links telefónicos | Z1: Dato pendiente | AA1: Google Maps | AB1: Fuente | AC1: URL fuente | AD1: Evidencia | AE1: Calidad del dato | AF1: Origen del registro | AG1: Servicios PRESOL a ofrecer | AH1: Rubro foco enriquecimiento | AI1: Ciudad foco solicitada | AJ1: Prioridad visita sugerida | AK1: Observación servicio nuevo | AL1: Fuente unificación | AM1: Notas de unificación
A2: RT-054 | B2: Pendiente | C2: Base Río Tercero | D2: Río Tercero / zona industrial | E2: Río Tercero | F2: A | G2: 100 | H2: Ascanelli S.A. | I2: Fabricante de tolvas, sembradoras, mixers y embolsadoras | J2: Maquinaria agrícola | K2: 03571 423691 | L2: OK | M2: logística / ventas / postventa | N2: Despacho de implementos, tolvas, sembradoras, estructuras, equipos terminados y componentes de gran porte hacia concesionarios, clientes, ferias o campo. | O2: Plataforma 20 tn para maquinaria/implementos + malacate e hidrogrúa según maniobra + seguro de carga + trazabilidad GPS. | P2: Proponer a PRESOL como transporte tercerizado para entregas, picos de producción, ferias y movimientos especiales sin inmovilizar flota propia. | Q2: Llamada comercial prioritaria; pedir por logística/ventas/postventa y consultar próximo equipo a trasladar. | S2: =IFERROR(T(INDEX('Prospectos Resumen'!$K$9:$K$297,MATCH(A2,'Prospectos Resumen'!$A$9:$A$297,0))),"") -> SERGIO ASCANELLI | X2: tel:+543571423691 | Y2: tel:+543571423691 | Z2: Confirmar decisor y frecuencia de traslados. | AA2: https://www.google.com/maps/search/?api=1&query=Ascanelli+S.A.+R%C3%ADo+Tercero+C%C3%B3rdoba+Argentina | AB2: AFAMAC / CIMCC | AC2: https://afamac.com.ar/catalogo/asociados-afamac/ascanelli/ | AD2: Fabricante radicado en Río Tercero; produce tolvas autodescargables, sembradoras, mixers y embolsadoras. | AE2: Alta | AF2: Rastrillaje agro-maquinaria web 2026-09-07 | AG2: plataforma 20 tn para maquinaria/implementos | hidrogrúa para maniobras | malacate | seguro de carga | trazabilidad GPS | AH2: fabricante/concesionario/servicio maquinaria agrícola | AI2: Sí | AJ2: Muy alta | AK2: Perfil específico maquinaria agrícola: validar pesos/dimensiones, tipo de carga y disponibilidad de medios de izaje antes de cotizar. | AL2: Rastrillaje agro-maquinaria 2026-09-07 | AM2: Alta nueva luego de barrido específico de fabricantes, implementos, tractores, concesionarios y agropartes; cruzada contra la base maestra para evitar duplicados.
A3: RT-001 | B3: Pendiente | C3: Base Río Tercero | D3: Río Tercero | E3: Río Tercero | F3: A | G3: 100 | H3: Hormicor | I3: Hormigón elaborado | J3: Hormigón, áridos y materiales | K3: 03571 500888 / 03571 510066 | L3: OK | M3: planta / mantenimiento | N3: Movimiento de premoldeados, equipos de planta/cantera, bombas, moldes y cargas pesadas. | O3: Movimiento de equipos de cantera/planta; transporte de material suelto sujeto a confirmar unidad o esquema operativo. | P3: Ofrecer respaldo para picos de obra y traslados de equipos. | Q3: Visita o llamada de validación; pedir próximo traslado concreto. | S3: =IFERROR(T(INDEX('Prospectos Resumen'!$K$9:$K$297,MATCH(A3,'Prospectos Resumen'!$A$9:$A$297,0))),"") | X3: tel:+543571500888 | Y3: tel:+543571500888 | tel:+543571510066 | Z3: Validar contacto decisor y necesidad inmediata. | AA3: https://www.google.com/maps/search/?api=1&query=-32.178000,-64.111000 | AB3: hormigonelaborado.com / Hormicor | AD3: Registro curado en documento de dirección PRESOL 2026-09. | AE3: Alta | AF3: Base curada PDF dirección | AG3: transporte de áridos/materiales | hidrogrúa para carga/descarga | percha para pallets/bolsones | AH3: áridos/construcción/premoldeados | AI3: Sí | AJ3: Muy alta | AK3: Áridos/materiales: confirmar modalidad de carga/descarga y tipo de unidad requerida antes de cotizar. | AL3: GPT adjunto + Hermes | AM3: Fusionado con base Hermes para completar teléfonos/fuentes/servicios.
A4: RT-002 | B4: Pendiente | C4: Base Río Tercero | D4: Río Tercero / zona industrial | E4: Río Tercero | F4: A | G4: 100 | H4: Metalúrgica Monticelli | I4: Fabricación de implementos agrícolas | J4: Maquinaria agrícola | K4: +54 3571 613058 / +54 3571 613060 | L4: OK | M4: logística / despacho / postventa | N4: Traslado de maquinaria, implementos, equipos terminados y componentes de gran porte entre planta, cliente, obra o feria. | O4: Plataforma 20 tn + malacate/hidrogrúa según maniobra + seguro de carga + trazabilidad GPS. | P4: Fabricante con más de 30 años, ubicado en RP6 km 3,5; produce rastras, rolos, terraceadoras y otros implementos. | Q4: Llamada prioritaria; pedir próximo traslado concreto y, si hay encaje, coordinar visita. | S4: =IFERROR(T(INDEX('Prospectos Resumen'!$K$9:$K$297,MATCH(A4,'Prospectos Resumen'!$A$9:$A$297,0))),"") -> GUILLERMO GOÑI | X4: tel:+543571613058 | Y4: tel:+543571613058 | tel:+543571613060 | Z4: Confirmar decisor, frecuencia de movimientos y vigencia del contacto antes de cotizar. | AA4: https://www.google.com/maps/search/?api=1&query=Metal%C3%BArgica+Monticelli+R%C3%ADo+Tercero+C%C3%B3rdoba+Argentina | AB4: Web propia Metalúrgica Monticelli | AC4: https://www.metalmonticelli.site/ | AD4: Fabricante con más de 30 años, ubicado en RP6 km 3,5; produce rastras, rolos, terraceadoras y otros implementos. | AE4: Alta | AF4: Enriquecimiento web 2026-09-07 | AG4: transporte de áridos/materiales | hidrogrúa para carga/descarga | percha para pallets/bolsones | plataforma 20 tn para maquinaria/piezas | hidrogrúa para maniobras | percha para pallets | AH4: fabricante/servicio maquinaria agrícola | AI4: Sí | AJ4: Muy alta | AL4: GPT adjunto
A5: RT-003 | B5: Pendiente | C5: Base Río Tercero | D5: Río Tercero | E5: Río Tercero | F5: A | G5: 100 | H5: Metalúrgica Novaretti | I5: Recipientes y equipos metalmecánicos | J5: Metalúrgica y fabricación | K5: 03571 414282 / 03571 606930 | L5: OK | M5: despacho / producción | N5: Despacho seguro de estructuras, carrozados, tanques, piezas industriales y equipos sobre plataforma. | O5: Despacho de estructuras, tanques, transformadores, piezas de ingeniería y equipos sobre plataforma 20 tn. | P5: Cotizar despacho recurrente a plantas/obras. | Q5: Visita o llamada de validación; pedir próximo traslado concreto. | S5: =IFERROR(T(INDEX('Prospectos Resumen'!$K$9:$K$297,MATCH(A5,'Prospectos Resumen'!$A$9:$A$297,0))),"") -> CRISTIAN NOVARETTI | X5: tel:+543571414282 | Y5: tel:+543571414282 | tel:+543571606930 | Z5: Validar contacto decisor y necesidad inmediata. | AA5: https://www.google.com/maps/search/?api=1&query=-32.169000,-64.117000 | AB5: novaretti.com.ar | AD5: Registro curado en documento de dirección PRESOL 2026-09. | AE5: Alta | AF5: Base curada PDF dirección | AG5: plataforma 20 tn para maquinaria/piezas | hidrogrúa para maniobras | percha para pallets | AH5: otro rubro factible | AI5: Sí | AJ5: Muy alta | AL5: GPT adjunto + Hermes | AM5: Fusionado con base Hermes para completar teléfonos/fuentes/servicios.
A6: RT-004 | B6: Pendiente | C6: Base Río Tercero | D6: Parque Industrial Leonardo Da Vinci | E6: Río Tercero | F6: A | G6: 100 | H6: Metalúrgica Río Tercero S.A. | I6: Equipamiento minero, vial y agroindustrial / fundición | J6: Metalúrgica y fabricación | K6: 03571 430558 | L6: OK | M6: despacho / producción | N6: Traslado de equipos de planta, silos, repuestos pesados, balanzas, implementos y cargas especiales. | O6: Transporte de repuestos/equipos/silos/implementos + coordinación de retiro y descarga. | P6: Produce equipamiento e insumos para minería, vial y agroindustria; encaje directo con cargas pesadas. | Q6: Validar teléfono/contacto; si responde, pedir un caso concreto de traslado o próximo movimiento. | S6: =IFERROR(T(INDEX('Prospectos Resumen'!$K$9:$K$297,MATCH(A6,'Prospectos Resumen'!$A$9:$A$297,0))),"") -> FEDE SERRA | X6: tel:+543571430558 | Y6: tel:+543571430558 | Z6: Confirmar decisor y vigencia del dato antes de incluir en salida prioritaria. | AA6: https://www.google.com/maps/search/?api=1&query=Metal%C3%BArgica+R%C3%ADo+Tercero+S.A.+R%C3%ADo+Tercero+C%C3%B3rdoba+Argentina | AB6: Maquinac / Parque Industrial Río Tercero | AC6: https://maquinac.com/empresas/metalurgica-rio-tercero | AD6: Maquinac informa dirección en Parque Industrial, teléfono y rubro minero/vial/agroindustrial. | AE6: Alta | AF6: Nuevo enriquecimiento 2026-09-02 | AG6: plataforma 20 tn para maquinaria/piezas | hidrogrúa para maniobras | percha para pallets | AH6: otro rubro factible | AI6: Sí | AJ6: Muy alta | AK6: Percha pallets: útil para insumos, bolsones, repuestos y materiales palletizados. | AL6: GPT adjunto + Hermes | AM6: Fusionado con base Hermes para completar teléfonos/fuentes/servicios.
A7: RT-005 | B7: Pendiente | C7: Base Río Tercero | D7: Río Tercero / Av. Savio | E7: Río Tercero | F7: A | G7: 100 | H7: NT Construcciones | I7: Obras civiles industriales / montaje | J7: Construcción y obra vial | K7: +54 9 3571 597645 | L7: OK | M7: operaciones / jefe de obra | N7: Traslado de maquinaria, módulos de obrador, estructuras, equipos y cargas pesadas entre frentes. | O7: Transporte especial de equipos/obrador + apoyo de hidrogrúa según maniobra + seguro/GPS. | P7: Obras civiles industriales, montaje de naves y mantenimiento en complejos fabriles; clientes industriales regionales. | Q7: Validar teléfono/contacto; si responde, pedir un caso concreto de traslado o próximo movimiento. | S7: =IFERROR(T(INDEX('Prospectos Resumen'!$K$9:$K$297,MATCH(A7,'Prospectos Resumen'!$A$9:$A$297,0))),"") | X7: tel:+5493571597645 | Y7: tel:+5493571597645 | Z7: Confirmar decisor y vigencia del dato antes de incluir en salida prioritaria. | AA7: https://www.google.com/maps/search/?api=1&query=NT+Construcciones+R%C3%ADo+Tercero+C%C3%B3rdoba+Argentina | AB7: Web propia NT Construcciones | AC7: https://ntconstrucciones.com | AD7: Servicios: obras civiles industriales, estructuras de hormigón, montaje de naves; teléfono y oficina publicados. | AE7: Alta | AF7: Nuevo enriquecimiento 2026-09-02 | AG7: transporte de áridos/materiales | hidrogrúa para carga/descarga | percha para pallets/bolsones | AH7: otro rubro factible | AI7: Sí | AJ7: Muy alta | AL7: GPT adjunto + Hermes | AM7: Fusionado con base Hermes para completar teléfonos/fuentes/servicios.
A8: RT-064 | B8: Pendiente | C8: Base Río Tercero | D8: Río Tercero / corredor agro | E8: Río Tercero | F8: A | G8: 100 | H8: SALA / Agrotecnología Sala — Río Tercero | I8: Concesionario John Deere / PLA / maquinaria agrícola / postventa | J8: Maquinaria agrícola | K8: +54 9 358 4843387 | L8: OK | M8: logística / entregas / usados / postventa / gerente comercial | N8: Entrega y retiro de tractores, cosechadoras, pulverizadoras, sembradoras e implementos; movimientos por ventas, canjes, usados, service, demostraciones y ferias. | O8: Plataforma 20 tn para equipos e implementos + malacate/hidrogrúa según maniobra + seguro de carga + trazabilidad GPS + coordinación de entrega. | P8: Tercerizar entregas y retiros para no inmovilizar flota propia; absorber picos de campaña, ventas, canjes y service fuera de zona con un proveedor regional. | Q8: Llamada prioritaria; pedir por logística/ventas/postventa y consultar cómo resuelven hoy el próximo equipo a entregar o retirar. | S8: =IFERROR(T(INDEX('Prospectos Resumen'!$K$9:$K$297,MATCH(A8,'Prospectos Resumen'!$A$9:$A$297,0))),"") | X8: tel:+5493584843387 | Y8: tel:+5493584843387 | Z8: Confirmar decisor de logística/entregas y frecuencia mensual de movimientos de equipos. | AA8: https://www.google.com/maps/search/?api=1&query=SALA+%2F+Agrotecnolog%C3%ADa+Sala+%E2%80%94+R%C3%ADo+Tercero+R%C3%ADo+Tercero+C%C3%B3rdoba+Argentina | AB8: Asociación de Concesionarios John Deere / SALA | AC8: https://acjd.com.ar/concesionarios/ | AD8: La Asociación de Concesionarios John Deere publica a Agrotecnología Sala con sucursal en Río Tercero; punto local sobre RP6. | AE8: Alta | AF8: Rastrillaje concesionarios agro 2026-09-07 | AG8: plataforma 20 tn para maquinaria agrícola | hidrogrúa para maniobras | malacate | seguro de carga | trazabilidad GPS | coordinación de entregas | AH8: concesionario agro / maquinaria agrícola | AI8: Sí | AJ8: Muy alta | AK8: Concesionario: preguntar específicamente cómo resuelven entregas, retiros de usados, canjes, service fuera de zona y traslados a exposiciones. | AL8: Rastrillaje concesionarios agro 2026-09-07 | AM8: Alta nueva del barrido específico de concesionarios, sucursales y multimarca agro; cruzada contra la base maestra para evitar duplicados.
A9: RT-006 | B9: Pendiente | C9: Base Río Tercero | D9: Río Tercero / zona industrial | E9: Río Tercero | F9: A | G9: 100 | H9: Sinfix SAS | I9: Sinfines para agro e industria | J9: Metalúrgica y fabricación | K9: +54 9 3571 405077 | L9: OK | M9: despacho / producción | N9: Despacho de estructuras, piezas, equipos y conjuntos metalmecánicos de gran porte hacia obras o clientes. | O9: Plataforma 20 tn para piezas/estructuras + seguro de carga + trazabilidad GPS + apoyo de hidrogrúa según maniobra. | P9: Fabrica sinfines para sectores agrícola, ganadero, minero y alimenticio; despacho nacional de piezas y conjuntos. | Q9: Llamada prioritaria; pedir próximo traslado concreto y, si hay encaje, coordinar visita. | S9: =IFERROR(T(INDEX('Prospectos Resumen'!$K$9:$K$297,MATCH(A9,'Prospectos Resumen'!$A$9:$A$297,0))),"") | X9: tel:+5493571405077 | Y9: tel:+5493571405077 | Z9: Confirmar decisor, frecuencia de movimientos y vigencia del contacto antes de cotizar. | AA9: https://www.google.com/maps/search/?api=1&query=Sinfix+SAS+R%C3%ADo+Tercero+C%C3%B3rdoba+Argentina | AB9: Web propia SINFIX | AC9: https://sinfix.com.ar/ | AD9: Fabrica sinfines para sectores agrícola, ganadero, minero y alimenticio; despacho nacional de piezas y conjuntos. | AE9: Alta | AF9: Enriquecimiento web 2026-09-07 | AG9: transporte de áridos/materiales | hidrogrúa para carga/descarga | percha para pallets/bolsones | plataforma 20 tn para maquinaria/piezas | hidrogrúa para maniobras | percha para pallets | AH9: otro rubro factible | AI9: Sí | AJ9: Muy alta | AK9: Percha pallets: útil para insumos, bolsones, repuestos y materiales palletizados. | AL9: GPT adjunto
A10: RT-007 | B10: Pendiente | C10: Base Río Tercero | D10: Río Tercero / zona industrial | E10: Río Tercero | F10: A | G10: 100 | H10: Suragro - Implementos Agrícolas | I10: Fabricación de maquinaria agrícola | J10: Maquinaria agrícola | K10: 03571 424574 | L10: OK | M10: logística / despacho / postventa | N10: Traslado de maquinaria, implementos, equipos terminados y componentes de gran porte entre planta, cliente, obra o feria. | O10: Plataforma 20 tn + malacate/hidrogrúa según maniobra + seguro de carga + trazabilidad GPS. | P10: Fabricante local de maquinaria agrícola; alto potencial de despachos de equipos terminados. | Q10: Llamada prioritaria; pedir próximo traslado concreto y, si hay encaje, coordinar visita. | S10: =IFERROR(T(INDEX('Prospectos Resumen'!$K$9:$K$297,MATCH(A10,'Prospectos Resumen'!$A$9:$A$297,0))),"") | X10: tel:+543571424574 | Y10: tel:+543571424574 | Z10: Confirmar decisor, frecuencia de movimientos y vigencia del contacto antes de cotizar. | AA10: https://www.google.com/maps/search/?api=1&query=Suragro+-+Implementos+Agr%C3%ADcolas+R%C3%ADo+Tercero+C%C3%B3rdoba+Argentina | AB10: Google Maps / ficha pública | AC10: https://www.google.com/maps/search/?api=1&query=Suragro+Implementos+Agr%C3%ADcolas+R%C3%ADo+Tercero+C%C3%B3rdoba+Argentina | AD10: Fabricante local de maquinaria agrícola; alto potencial de despachos de equipos terminados. | AE10: Alta | AF10: Enriquecimiento web 2026-09-07 | AG10: transporte de áridos/materiales | hidrogrúa para carga/descarga | percha para pallets/bolsones | plataforma 20 tn para maquinaria/piezas | hidrogrúa para maniobras | percha para pallets | AH10: fabricante/servicio maquinaria agrícola | AI10: Sí | AJ10: Muy alta | AL10: GPT adjunto
A11: RT-008 | B11: Pendiente | C11: Base Río Tercero | D11: Río Tercero | E11: Río Tercero | F11: A | G11: 100 | H11: Tres Eme S.A. | I11: Silos y mecanización | J11: Agro, acopio y cooperativas | K11: 03571 432190 / 03571 637720 | L11: OK | M11: responsable de acopio / mantenimiento | N11: Traslado de equipos de planta, silos, repuestos pesados, balanzas, implementos y cargas especiales. | O11: Movimiento de equipos de planta, silos, balanzas, repuestos y cargas especiales para acopios/agroindustria. | P11: Ofrecer flete + descarga/posicionamiento en obra rural. | Q11: Visita o llamada de validación; pedir próximo traslado concreto. | S11: =IFERROR(T(INDEX('Prospectos Resumen'!$K$9:$K$297,MATCH(A11,'Prospectos Resumen'!$A$9:$A$297,0))),"") -> MATI MENGO | X11: tel:+543571432190 | Y11: tel:+543571432190 | tel:+543571637720 | Z11: Validar contacto decisor y necesidad inmediata. | AA11: https://www.google.com/maps/search/?api=1&query=-32.181000,-64.103000 | AB11: parqueindustrial.riotercero.gob.ar/empresa/Tres-Eme-S.A. | AD11: Registro curado en documento de dirección PRESOL 2026-09. | AE11: Alta | AF11: Base curada PDF dirección | AG11: plataforma 20 tn para maquinaria/piezas | hidrogrúa para maniobras | percha para pallets | percha para pallets de insumos | hidrogrúa para equipos/mantenimiento | barquilla para trabajos en altura | AH11: otro rubro factible | AI11: Sí | AJ11: Muy alta | AL11: GPT adjunto + Hermes | AM11: Fusionado con base Hermes para completar teléfonos/fuentes/servicios.
A12: RT-009 | B12: Pendiente | C12: Base Río Tercero | D12: Río Tercero | E12: Río Tercero | F12: A | G12: 100 | H12: Vial del Centro | I12: Obras de infraestructura vial | J12: Construcción y obra vial | K12: 0351 6411413 | L12: OK | M12: operaciones / entregas | N12: Traslado de maquinaria, módulos de obrador, estructuras, equipos y cargas pesadas entre frentes. | O12: Entrega y descarga de módulos/containers con plataforma, malacate e hidrogrúa según maniobra. | P12: Pedir próximo movimiento de maquinaria entre frentes. | Q12: Visita o llamada de validación; pedir próximo traslado concreto. | S12: =IFERROR(T(INDEX('Prospectos Resumen'!$K$9:$K$297,MATCH(A12,'Prospectos Resumen'!$A$9:$A$297,0))),"") | X12: tel:+543516411413 | Y12: tel:+543516411413 | Z12: Validar contacto decisor y necesidad inmediata. | AA12: https://www.google.com/maps/search/?api=1&query=-32.183000,-64.101000 | AB12: Parque Industrial Río Tercero | AD12: Registro curado en documento de dirección PRESOL 2026-09. | AE12: Alta | AF12: Base curada PDF dirección | AG12: transporte de áridos/materiales | hidrogrúa para carga/descarga | percha para pallets/bolsones | AH12: otro rubro factible | AI12: Sí | AJ12: Muy alta | AL12: GPT adjunto + Hermes | AM12: Fusionado con base Hermes para completar teléfonos/fuentes/servicios.
A13: RT-010 | B13: Pendiente | C13: Base Río Tercero | D13: Río Tercero / zona industrial | E13: Río Tercero | F13: A | G13: 96 | H13: HORMIWORK S.A. | I13: Premoldeados de hormigón pulido | J13: Hormigón, áridos y materiales | K13: 03571 565662 (portería parque) | L13: Verificar | M13: planta / despacho | N13: Movimiento de premoldeados, moldes, equipos de planta y cargas pesadas asociadas a obra. | O13: Transporte de premoldeados/equipos en plataforma + coordinación de descarga/posicionamiento con hidrogrúa cuando aplique. | P13: Empresa radicada para fabricar premoldeados de hormigón pulido; contacto por correo/parque. | Q13: Llamada prioritaria; pedir próximo traslado concreto y, si hay encaje, coordinar visita. | S13: =IFERROR(T(INDEX('Prospectos Resumen'!$K$9:$K$297,MATCH(A13,'Prospectos Resumen'!$A$9:$A$297,0))),"") | X13: tel:+543571565662 | Y13: tel:+543571565662 | Z13: Confirmar decisor, frecuencia de movimientos y vigencia del contacto antes de cotizar. | AA13: https://www.google.com/maps/search/?api=1&query=HORMIWORK+S.A.+R%C3%ADo+Tercero+C%C3%B3rdoba+Argentina | AB13: Parque Industrial Río Tercero | AC13: https://parqueindustrial.riotercero.gob.ar/empresa/HORMIWORK-S.A. | AD13: Empresa radicada para fabricar premoldeados de hormigón pulido; contacto por correo/parque. | Ficha del parque: fabricación de premoldeados de hormigón pulido; dirección E. del Campo 1271; contacto hormiwork@gmail.com. | AE13: Media | AF13: Enriquecimiento web 2026-09-07 | AG13: transporte de áridos/materiales | hidrogrúa para carga/descarga | percha para pallets/bolsones | AH13: áridos/construcción/premoldeados | AI13: Sí | AJ13: Alta | AK13: Áridos/materiales: confirmar modalidad de carga/descarga y tipo de unidad requerida antes de cotizar. | AL13: GPT adjunto + Hermes | AM13: Fusionado con base Hermes para completar teléfonos/fuentes/servicios. | ID fuente: RT-016
